Workbook

Sheet Model
A1: Dam ID | B1: Farm | C1: Dam | G1: Sample Type | H1: Age Class | I1: Age (Months) | J1: Collection Date (Dam) | L1: Preg. Outcome | M1: Calf ID | N1: Farm | O1: Calf | S1: Sample Type | T1: Calf Sex | U1: Collection Date (Calf) | W1: Calf Birth Date | X1: Colostrum ID | Y1: Farm | Z1: Colostrum | AB1: Notes
C2: Pre-Status | E2: Post-Status | O2: Birth Status | Q2: Post-Status
C3: ELISA | D3: PCR | E3: ELISA | F3: PCR | J3: Pre | K3: Post | O3: ELISA | P3: PCR | Q3: ELISA | R3: PCR | U3: Pre | V3: Post | Z3: ELISA | AA3: PCR
A4: 6 | B4: W | C4: Neg | E4: Neg | G4: Blood | L4: Calved | M4: 114 | N4: W | O4: Neg | Q4: Neg | S4: Blood | T4: F | U4: 45272 | V4: 45476
A5: 39 | B5: W | C5: Neg | E5: Neg | G5: Blood | L5: Calved | M5: 302 | N5: W | O5: Neg | Q5: Neg | S5: Blood | T5: F | U5: 45272 | V5: 45476
A6: 54P | B6: W | C6: Pos | E6: Pos | F6: Pos | G6: Blood | L6: Calved | M6: 1906 | N6: W | O6: Pos | Q6: Pos | S6: Blood | T6: F | U6: 45272 | V6: 45476
A7: 21 | B7: W | C7: Neg | G7: Blood
A8: 19 | B8: W | C8: Neg | G8: Blood
A9: H-39 | B9: W | C9: Pos | G9: Blood
A10: 11 | B10: W | C10: Neg | E10: Neg | G10: Blood | L10: Calved | M10: 205 | N10: W | O10: Neg | S10: Blood | T10: M | U10: 45272 | V10: 45476
A11: 23 | B11: W | C11: Neg | E11: Neg | G11: Blood
A12: 61 | B12: W | C12: Neg | E12: Neg | G12: Blood | L12: Calved | M12: 303 | N12: W | O12: Neg | Q12: Neg | S12: Blood | T12: F | U12: 45272 | V12: 45476
A13: 62B | B13: W | C13: Neg | E13: Neg | G13: Blood | L13: Calved | M13: 404 | N13: W | O13: Neg | Q13: Neg | S13: Blood | T13: M | U13: 45272 | V13: 45476
A14: 20 | B14: W | C14: Neg | E14: Neg | G14: Blood | L14: Calved | M14: 211 | N14: W | O14: Neg | S14: Blood | T14: F | U14: 45272 | V14: 45476
A15: 38P | B15: W | C15: Neg | E15: Neg | G15: Blood | L15: Stillbirth
A16: 7 | B16: W | C16: Neg | E16: Neg | G16: Blood | L16: Calved | M16: 111 | N16: W | O16: Neg | Q16: Neg | S16: Blood | T16: F | U16: 45272 | V16: 45476
A17: 14 | B17: W | C17: Neg | E17: Neg | G17: Blood | L17: Calved | M17: 300 | N17: W | O17: Neg | S17: Blood | T17: M | U17: 45272 | V17: 45476
A18: G | B18: W | C18: Neg | G18: Blood | L18: Calved | M18: 201 | N18: W | O18: Neg | S18: Blood | T18: ? | U18: 45272 | V18: 45476 | AB18: G-culled
A19: 60 | B19: W | C19: Neg | E19: Neg | G19: Blood | L19: Calved | M19: 301F | N19: W | O19: Neg | Q19: Neg | S19: Blood | T19: F | U19: 45272 | V19: 45476
A20: BW | B20: W | C20: Neg | G20: Blood
A21: BT | B21: W | C21: Neg | G21: Blood
A22: P | B22: W | C22: Neg | G22: Blood
A23: 51 | B23: W | C23: Neg | E23: Neg | G23: Blood | L23: Calved | M23: 305 | N23: W | O23: Neg | Q23: Neg | S23: Blood | T23: F | U23: 45272 | V23: 45476
A24: 42P | B24: W | C24: Neg | E24: Neg | G24: Blood
A25: 37P | B25: W | C25: Neg | E25: Neg | G25: Blood | L25: Calved | M25: 401F | N25: W | O25: Neg | Q25: Neg | S25: Blood | T25: F | U25: 45272 | V25: 45476
A26: 22 | B26: W | C26: Neg | E26: Neg | G26: Blood | L26: Stillbirth
A27: 99 | B27: W | C27: Neg | G27: Blood
A28: 53 | B28: W | C28: Neg | E28: Neg | G28: Blood | L28: Calved | M28: 301M | N28: W | O28: Doub | Q28: Neg | S28: Blood | T28: M | U28: 45272 | V28: 45476
A29: 24 | B29: W | C29: Neg | G29: Blood
A30: X | B30: W | C30: Neg | G30: Blood
A31: 8 | B31: W | C31: Neg | E31: Neg | G31: Blood | L31: Calved | M31: 209 | N31: W | O31: Neg | Q31: Neg | S31: Blood | T31: F | U31: 45272 | V31: 45476
A32: 453 | B32: W | C32: Neg | G32: Blood
A33: 9 | B33: W | C33: Neg | G33: Blood
A34: 64P | B34: W | C34: Neg | G34: Blood | L34: Calved | M34: 401M | N34: W | O34: Neg | Q34: Neg | S34: Blood | T34: M | U34: 45272 | V34: 45476
A35: 1P | B35: W | C35: Neg | G35: Blood
A36: 73P | B36: W | C36: Neg | G36: Blood
A37: 50 | B37: W | C37: Pos | G37: Blood
A38: R | B38: W | C38: Neg | G38: Milk
A39: 3 | B39: W | E39: Neg | G39: Blood | L39: Calved | M39: 112 | N39: W | O39: Neg | S39: Blood | T39: M | U39: 45272 | V39: 45476
A41: 878 | B41: NC | C41: Neg | G41: Milk | J41: 45145 | L41: Calved | M41: 4 | N41: NC | O41: ? | S41: Blood | T41: F? | W41: 45445
...

Sheet Values
A1: VALUES | B1: PH | C1: GN | D1: NM | E1: WR | F1: SV | G1: NC | H1: TOTAL | J1: Notation | K1: Definition | L1: VALUES
A2: Number of eligible cows for insemination | B2: 182 | C2: 490 | D2: 285 | E2: 35 | G2: 160 | H2: =SUM(B2:G2) -> 1152 | I2: * | J2: ϴ | K2: Buying or selling rate of animals | L2: Derived from model
A3: Number of cows inseminated | B3: 148 | C3: 105 | D3: 161 | E3: 36 | G3: 132 | H3: 614 | J3: α | K3: Pregnancy rate | L3: =H16 -> 0.43155695
A4: Number of confirmed pregnancies (Total) | B4: 139 | C4: 101 | D4: 84 | E4: 17 | G4: 72 | H4: =SUM(B4:G4) -> 413 | J4: p | K4: Probability that a new animal is infected | L4: 0.3
A5: Number of confirmed pregnancies (Uninfected) | B5: 49 | C5: 64 | D5: 50 | E5: 16 | G5: 52 | H5: =SUM(B5:G5) -> 231 | J5: βS | K5: Abortion rate of susceptible | L5: =H17 -> 0.051948052
A6: Number of confirmed pregnancies (Infected) | B6: 57 | C6: 39 | D6: 54 | E6: 1 | G6: 19 | H6: =SUM(B6:G6) -> 170 | J6: βI | K6: Abortion rate of infected animals | L6: =H18 -> 0.16470588
A7: Number of Abortions (Uninfected) | B7: 1 | C7: 2 | D7: 4 | E7: 2 | G7: 3 | H7: =SUM(B7:G7) -> 12 | J7: ρh | K7: Horizontal infection rate | L7: =H19 -> 0.15261044
A8: Number of Abortions (Infected) | B8: 4 | C8: 4 | D8: 19 | E8: 0 | G8: 1 | H8: =SUM(B8:G8) -> 28 | J8: ρv1 | K8: Vertical transmission probability | L8: ='VHT Adj.'!I15 -> 0.58526735
A9: Number of infected calfs from uninfected dams | B9: 11 | C9: 9 | D9: 10 | E9: 0 | G9: 8 | H9: =SUM(B9:G9) -> 38 | J9: ζ | K9: Prevalence dependent factor | L9: 0.028 | M9: *
A10: Total number of calfs from uninfected dams | B10: 58 | C10: 81 | D10: 45 | E10: 15 | G10: 50 | H10: =SUM(B10:G10) -> 249 | J10: δ | K10: Mortality rate | L10: 0.02 | M10: **
A11: Number of infected calfs from infected dams | B11: 33 | C11: 9 | D11: 24 | E11: 1 | G11: 4 | H11: =SUM(B11:G11) -> 71 | J11: ϵ | K11: Removal rate | L11: 0.095 | M11: *
A12: Total number of calfs from infected dams | B12: 78 | C12: 21 | D12: 39 | E12: 1 | G12: 13 | H12: =SUM(B12:G12) -> 152 | J12: σ | K12: External transmission coefficient | L12: 0-0.07 | M12: *
J13: c | K13: Culling proportion | L13: 0.7 | M13: *
A14: Heat Detection Rate | B14: =B3/B2 -> 0.81318681 | C14: =C3/C2 -> 0.21428571 | D14: =D3/D2 -> 0.56491228 | E14: =E3/E2 -> 1.0285714 | G14: =G3/G2 -> 0.825 | H14: =H3/957 -> 0.6415883 | J14: Sp | K14: Specificity of serological test | L14: 0.989 | M14: *
A15: Conception Rate | B15: =B4/B3 -> 0.93918919 | C15: =C4/C3 -> 0.96190476 | D15: =D4/D3 -> 0.52173913 | E15: =E4/E3 -> 0.47222222 | G15: =G4/G3 -> 0.54545455 | H15: =H4/H3 -> 0.67263844 | J15: Se | K15: Sensitivity of serological test | L15: 0.996 | M15: *
A16: PREGNANCY RATE | B16: =B14*B15 -> 0.76373626 | C16: =C14*C15 -> 0.20612245 | D16: =D14*D15 -> 0.29473684 | E16: =E14*E15 -> 0.48571429 | G16: =G14*G15 -> 0.45 | H16: =H14*H15 -> 0.43155695
A17: ABORTION RATE (SUCEPTIBLE) | B17: =B7/B5 -> 0.020408163 | C17: =C7/C5 -> 0.03125 | D17: =D7/D5 -> 0.08 | E17: =E7/E5 -> 0.125 | G17: =G7/G5 -> 0.057692308 | H17: =H7/H5 -> 0.051948052
A18: ABORTION RATE (INFECTED) | B18: =B8/B6 -> 0.070175439 | C18: =C8/C6 -> 0.1025641 | D18: =D8/D6 -> 0.35185185 | E18: =E8/E6 -> 0 | G18: =G8/G6 -> 0.052631579 | H18: =H8/H6 -> 0.16470588
A19: HORIZONTAL TRANSMISSION | B19: =B9/B10 -> 0.18965517 | C19: =C9/C10 -> 0.11111111 | D19: =D9/D10 -> 0.22222222 | E19: =E9/E10 -> 0 | G19: =G9/G10 -> 0.16 | H19: =H9/H10 -> 0.15261044
A20: VERTICAL TRANSMISSION | B20: =B11/B12 -> 0.42307692 | C20: =C11/C12 -> 0.42857143 | D20: =D11/D12 -> 0.61538462 | E20: =E11/E12 -> 1 | G20: =G11/G12 -> 0.30769231 | H20: =H11/H12 -> 0.46710526

Sheet VHT Adj. CP
A1: CALF | B1: DAM | F1: PPV | G1: 0.974
B2: Pos | C2: Neg | D2: Total
A3: Pos | B3: =Values!H11 -> 71 | C3: =Values!H9 -> 38 | D3: =B3+C3 -> 109 | F3: NPV | G3: 0.998 | H3: Uncorrected values
A4: Neg | B4: =81 -> 81 | C4: =212 -> 212 | D4: =B4+C4 -> 293 | H4: VT | I4: =B3/B5 -> 0.46757284
A5: Total | B5: =B3+B4-0.152 -> 151.848 | C5: =C3+C4+0.152 -> 250.152 | H5: HT | I5: =C3/C5 -> 0.15190764
A7: Observed | B7: Corrected - imperfect test
B8: A | C8: B | D8: C | E8: D
A9: A | B9: =B3*G1*G1 -> 67.355996 | C9: =B3*G1*(1-G1) -> 1.798004 | D9: =B3*(1-G1)*G1 -> 1.798004 | E9: =B3*(1-G1)*(1-G1) -> 0.047996
A10: B | B10: =C3*G1*(1-G3) -> 0.074024 | C10: =C3*G1*G3 -> 36.937976 | D10: =C3*(1-G3)*(1-G1) -> 0.001976 | E10: =C3*(1-G3)*G3 -> 0.075848
A11: C | B11: =B4*(1-G3)*G1 -> 0.157788 | C11: =B4*(1-G3)*(1-G1) -> 0.004212 | D11: =B4*G3*G1 -> 78.736212 | E11: =B4*G3*(1-G1) -> 2.101788
A12: D | B12: =C4*(1-G3)*(1-G3) -> 0.000848 | C12: =C4*(1-G1)*G3 -> 5.500976 | D12: =C4*G3*(1-G3) -> 0.423152 | E12: =C4*G3*G3 -> 211.15285
A13: Correct. Freq. | B13: =SUM(B9:B12) -> 67.588656 | C13: =SUM(C9:C12) -> 44.241168 | D13: =SUM(D9:D12) -> 80.959344 | E13: =SUM(E9:E12) -> 213.37848
A15: No need to apply a further correction for bias in HT because we sampled at birth
A18: Observed | B18: Corrected - HT in calves from pos dam | H18: Adj. value
B19: A | C19: B | D19: C | E19: D
A20: A | B20: =B14*G12*G12 -> 0 | D20: =B14*(1-G12)*G12 -> 0 | H20: VT | I20: =B24/SUM(B24,D24) -> 0.341996
A21: B | B21: =C14*G12*(1-G14) -> 0 | D21: =C14*(1-G14)*(1-G12) -> 0 | H21: HT | I21: =C24/SUM(C24,E24) -> 0.17173057
A22: C | B22: =B15*(1-G14)*G12 -> 0 | D22: =B15*G14*G12 -> 0
A23: D | B23: =C15*(1-G14)*(1-G14) -> 0 | D23: =C15*G14*(1-G14) -> 0
A24: Correct. Freq. | B24: =(B13-(B13+D13)*I21)/(1-I21) -> 50.802821 | C24: =C13 -> 44.241168 | D24: =SUM(B13,D13)-B24 -> 97.745179 | E24: =E13 -> 213.37848

Sheet VHT Adj.
A1: CALF | B1: DAM | F1: PPV | G1: 0.974
B2: Pos | C2: Neg | D2: Total
A3: Pos | B3: =Values!H11-0.152 -> 70.848 | C3: =Values!H9+0.152 -> 38.152 | D3: =B3+C3 -> 109 | F3: NPV | G3: 0.998
A4: Neg | B4: =81-0.152 -> 80.848 | C4: =212+0.152 -> 212.152 | D4: =B4+C4 -> 293
A5: Total | B5: =B3+B4-0.152 -> 151.544 | C5: =C3+C4+0.152 -> 250.456
A7: Observed | B7: Corrected | H7: Adj. H infection in Dams | I7: =C3/(C3+C4) -> 0.15242265
B8: A | C8: B | D8: C | E8: D
A9: A | B9: =B3*G1*G1 -> 67.211797 | C9: =B3*G1*(1-G1) -> 1.7941548 | D9: =B3*(1-G1)*G1 -> 1.7941548 | E9: =B3*(1-G1)*(1-G1) -> 0.047893248
A10: B | B10: =C3*G1*(1-G3) -> 0.074320096 | C10: =C3*G1*G3 -> 37.085728 | D10: =C3*(1-G3)*(1-G1) -> 0.001983904 | E10: =C3*(1-G1)*G3 -> 0.9899681 | H10: VT | I10: =B3/(B3+B4) -> 0.46703934
A11: C | B11: =B4*(1-G3)*G1 -> 0.1574919 | C11: =B4*(1-G3)*(1-G1) -> 0.004204096 | D11: =B4*G3*G1 -> 78.58846 | E11: =B4*G3*(1-G1) -> 2.0978439 | H11: HT | I11: =C3/(C3+C4) -> 0.15242265
A12: D | B12: =C4*(1-G3)*(1-G3) -> 0.000848608 | C12: =C4*(1-G1)*G3 -> 5.5049201 | D12: =C4*G3*(1-G1) -> 5.5049201 | E12: =C4*G3*G3 -> 211.30424
A13: Correct. Freq. | B13: =SUM(B9:B12) -> 67.444458 | C13: =SUM(C9:C12) -> 44.389007 | D13: =SUM(D9:D12) -> 85.889519 | E13: =SUM(E9:E12) -> 214.43995 | H13: Adj.
H15: VT | I15: =B13/(B3+C13) -> 0.58526735
H16: HT | I16: =D13/(D13+E13) -> 0.28598432

Sheet Sheet1
A1: Time (Year) | B1: Scenarios
B2: Do Nothing (A) | C2: Do Nothing (B) | D2: Test New Animals (A) | E2: Test New Animals (B) | F2: Test and Cull (A) | G2: Test and Cull (B)
B3: Prevalence (%)
A4: 0 | B4: 32 | C4: 32 | D4: 32 | E4: 32 | F4: 32 | G4: 32
A5: 2.5 | B5: 28.82 | C5: 17.84 | D5: 26.12 | E5: 17.7 | F5: 11 | G5: 7.73
A6: 5 | B6: 28.22 | C6: 11.72 | D6: 23.78 | E6: 11.7 | F6: 6.25 | G6: 1.9
A7: 7.5 | B7: 28.01 | C7: 9.4 | D7: 22.59 | E7: 6.9 | F7: 5.27 | G7: 0.59
A8: 10 | B8: 27.95 | C8: 8.53 | D8: 21.88 | E8: 5.9 | F8: 5.13 | G8: 0.11
